I'm sorry, but an uncaught exception occurred.

While running game code:
  File "game/script.rpy", line 42, in script
    м "Привет! У меня 247. Буду кидать оригиналы в Томский Политех. У тебя что по планам?"
Exception: Sayer 'м' is not defined.

-- Full Traceback ------------------------------------------------------------

Full traceback:
  File "game/script.rpy", line 42, in script
    м "Привет! У меня 247. Буду кидать оригиналы в Томский Политех. У тебя что по планам?"
  File "C:\Apps\RenPy\renpy-8.3.4-sdk\renpy\ast.py", line 2586, in execute
    Say.execute(self)
  File "C:\Apps\RenPy\renpy-8.3.4-sdk\renpy\ast.py", line 583, in execute
    who = eval_who(self.who, self.who_fast)
  File "C:\Apps\RenPy\renpy-8.3.4-sdk\renpy\ast.py", line 472, in eval_who
    raise Exception("Sayer '%s' is not defined." % who)
Exception: Sayer 'м' is not defined.

Windows-10-10.0.19045 AMD64
Ren'Py 8.3.7.25031702
HronikiObshagi 1.0
Thu Jun 19 20:02:15 2025
