I'm sorry, but an uncaught exception occurred.

While running game code:
  File "game/script.rpy", line 110, in script
    nvl_kl "Ребята, пришли результаты ЕГЭ по информатике! Хвастайтесь!"
Exception: Sayer 'nvl_kl' is not defined.

-- Full Traceback ------------------------------------------------------------

Full traceback:
  File "game/script.rpy", line 110, in script
    nvl_kl "Ребята, пришли результаты ЕГЭ по информатике! Хвастайтесь!"
  File "C:\Apps\RenPy\renpy-8.3.4-sdk\renpy\ast.py", line 2586, in execute
    Say.execute(self)
  File "C:\Apps\RenPy\renpy-8.3.4-sdk\renpy\ast.py", line 583, in execute
    who = eval_who(self.who, self.who_fast)
  File "C:\Apps\RenPy\renpy-8.3.4-sdk\renpy\ast.py", line 472, in eval_who
    raise Exception("Sayer '%s' is not defined." % who)
Exception: Sayer 'nvl_kl' is not defined.

Windows-10-10.0.19045 AMD64
Ren'Py 8.3.7.25031702
HronikiObshagi 0.0.1 pre-alpha-version
Sun Jun 22 20:42:30 2025
